<?xml version="1.0" ?>
<!-- =================================================================================== -->
<!-- |    This document was autogenerated by xacro from standalone_mico_arm.xacro      | -->
<!-- |    EDITING THIS FILE BY HAND IS NOT RECOMMENDED                                 | -->
<!-- =================================================================================== -->
<robot name="mico" xmlns:body="http://playerstage.sourceforge.net/gazebo/xmlschema/#body" xmlns:controller="http://playerstage.sourceforge.net/gazebo/xmlschema/#controller" xmlns:gazebo="http://playerstage.sourceforge.net/gazebo/xmlschema/#gz" xmlns:geom="http://playerstage.sourceforge.net/gazebo/xmlschema/#geom" xmlns:interface="http://playerstage.sourceforge.net/gazebo/xmlschema/#interface" xmlns:joint="http://playerstage.sourceforge.net/gazebo/xmlschema/#joint" xmlns:model="http://playerstage.sourceforge.net/gazebo/xmlschema/#model" xmlns:physics="http://playerstage.sourceforge.net/gazebo/xmlschema/#physics" xmlns:renderable="http://playerstage.sourceforge.net/gazebo/xmlschema/#renderable" xmlns:rendering="http://playerstage.sourceforge.net/gazebo/xmlschema/#rendering" xmlns:sensor="http://playerstage.sourceforge.net/gazebo/xmlschema/#sensor" xmlns:xacro="http://ros.org/wiki/xacro" xmlns:xi="http://www.w3.org/2001/XInclude">
  <link name="root">
    <visual>
      <origin rpy="0 0 0" xyz="0 0 0"/>
      <geometry>
        <box size="0 0 0"/>
        <!--making it slightly bigger in x and z direction-->
      </geometry>
      <!--<material name="Black" /> -->
    </visual>
    <collision>
      <origin rpy="0 0 0" xyz="0 0 0"/>
      <geometry>
        <box size="0 0 0"/>
        <!--making it slightly bigger in x and z direction-->
      </geometry>
    </collision>
  </link>
  <link name="mico_link_base">
    <visual>
      <geometry>
        <mesh filename="package://jaco_model/meshes/mico_link_base.dae"/>
      </geometry>
      <material name="carbon_fiber">
        <color rgba="0.792156862745098 0.819607843137255 0.933333333333333 1"/>
      </material>
    </visual>
    <collision>
      <geometry>
        <mesh filename="package://jaco_model/meshes/mico_link_base.dae"/>
      </geometry>
    </collision>
  </link>
  <joint name="mico_joint_base" type="fixed">
    <parent link="root"/>
    <child link="mico_link_base"/>
    <axis xyz="0 0 0"/>
    <origin rpy="0 0 0" xyz="0 0 0"/>
  </joint>
  <link name="mico_link_1">
    <visual>
      <geometry>
        <mesh filename="package://jaco_model/meshes/mico_link_1.dae"/>
      </geometry>
      <material name="carbon_fiber">
        <color rgba="0.792156862745098 0.819607843137255 0.933333333333333 1"/>
      </material>
    </visual>
    <collision>
      <geometry>
        <mesh filename="package://jaco_model/meshes/mico_link_1.dae"/>
      </geometry>
    </collision>
  </link>
  <joint name="mico_joint_1" type="revolute">
    <parent link="mico_link_base"/>
    <child link="mico_link_1"/>
    <axis xyz="0 0 -1"/>
    <origin rpy="3.14159265359 0 3.14159265359" xyz="0 0 0.1535"/>
    <limit effort="30" lower="-6.28318530718" upper="6.28318530718" velocity="5"/>
  </joint>
  <link name="mico_link_2">
    <visual>
      <geometry>
        <mesh filename="package://jaco_model/meshes/mico_link_2.dae"/>
      </geometry>
      <material name="carbon_fiber">
        <color rgba="0.792156862745098 0.819607843137255 0.933333333333333 1"/>
      </material>
    </visual>
    <collision>
      <geometry>
        <mesh filename="package://jaco_model/meshes/mico_link_2.dae"/>
      </geometry>
    </collision>
  </link>
  <joint name="mico_joint_2" type="revolute">
    <parent link="mico_link_1"/>
    <child link="mico_link_2"/>
    <axis xyz="0 0 1"/>
    <origin rpy="-1.57079632679 3.14159265359 0" xyz="0 0 -0.1185"/>
    <limit effort="30" lower="0" upper="6.28318530718" velocity="5"/>
  </joint>
  <link name="mico_link_3">
    <visual>
      <geometry>
        <mesh filename="package://jaco_model/meshes/mico_link_3.dae"/>
      </geometry>
      <material name="carbon_fiber">
        <color rgba="0.792156862745098 0.819607843137255 0.933333333333333 1"/>
      </material>
    </visual>
    <collision>
      <geometry>
        <mesh filename="package://jaco_model/meshes/mico_link_3.dae"/>
      </geometry>
    </collision>
  </link>
  <joint name="mico_joint_3" type="revolute">
    <parent link="mico_link_2"/>
    <child link="mico_link_3"/>
    <axis xyz="0 0 -1"/>
    <origin rpy="3.14159265359 0 1.57079632679" xyz="0.41 0 0"/>
    <limit effort="30" lower="0" upper="6.28318530718" velocity="5"/>
  </joint>
  <link name="mico_link_4">
    <visual>
      <geometry>
        <mesh filename="package://jaco_model/meshes/mico_link_4.dae"/>
      </geometry>
      <material name="carbon_fiber">
        <color rgba="0.792156862745098 0.819607843137255 0.933333333333333 1"/>
      </material>
    </visual>
    <collision>
      <geometry>
        <mesh filename="package://jaco_model/meshes/mico_link_4.dae"/>
      </geometry>
    </collision>
  </link>
  <joint name="mico_joint_4" type="revolute">
    <parent link="mico_link_3"/>
    <child link="mico_link_4"/>
    <axis xyz="0 0 -1"/>
    <origin rpy="3.14159265359 1.57079632679 0" xyz="0.207 0 -0.01125"/>
    <limit effort="30" lower="-6.28318530718" upper="6.28318530718" velocity="5"/>
  </joint>
  <link name="mico_link_5">
    <visual>
      <geometry>
        <mesh filename="package://jaco_model/meshes/mico_link_5.dae"/>
      </geometry>
      <material name="carbon_fiber">
        <color rgba="0.792156862745098 0.819607843137255 0.933333333333333 1"/>
      </material>
    </visual>
    <collision>
      <geometry>
        <mesh filename="package://jaco_model/meshes/mico_link_5.dae"/>
      </geometry>
    </collision>
  </link>
  <joint name="mico_joint_5" type="revolute">
    <parent link="mico_link_4"/>
    <child link="mico_link_5"/>
    <axis xyz="0 0 -1"/>
    <origin rpy="0 -0.959931088597 0" xyz="0.0343 0 -0.06588"/>
    <limit effort="30" lower="-6.28318530718" upper="6.28318530718" velocity="5"/>
  </joint>
  <link name="mico_link_hand">
    <visual>
      <geometry>
        <mesh filename="package://jaco_model/meshes/mico_link_hand.dae"/>
      </geometry>
      <material name="carbon_fiber">
        <color rgba="0.792156862745098 0.819607843137255 0.933333333333333 1"/>
      </material>
    </visual>
    <collision>
      <geometry>
        <mesh filename="package://jaco_model/meshes/mico_link_hand.dae"/>
      </geometry>
    </collision>
  </link>
  <joint name="mico_joint_6" type="revolute">
    <parent link="mico_link_5"/>
    <child link="mico_link_hand"/>
    <axis xyz="0 0 -1"/>
    <origin rpy="-0.959931088597 0 1.57079632679" xyz="0.0343 0 -0.06588"/>
    <limit effort="30" lower="-6.28318530718" upper="6.28318530718" velocity="5"/>
  </joint>
  <link name="mico_link_finger_1">
    <visual>
      <geometry>
        <mesh filename="package://jaco_model/meshes/mico_link_finger_1.dae"/>
      </geometry>
      <material name="carbon_fiber">
        <color rgba="0.792156862745098 0.819607843137255 0.933333333333333 1"/>
      </material>
    </visual>
    <collision>
      <geometry>
        <mesh filename="package://jaco_model/meshes/mico_link_finger_1.dae"/>
      </geometry>
    </collision>
  </link>
  <joint name="mico_joint_finger_1" type="revolute">
    <parent link="mico_link_hand"/>
    <child link="mico_link_finger_1"/>
    <axis xyz="0 0 1"/>
    <origin rpy="-1.5708 0 0" xyz="0.030948 0.013746 -0.11107 "/>
    <limit effort="30" lower="0" upper="0.698131700798" velocity="5"/>
  </joint>
  <link name="mico_link_finger_2">
    <visual>
      <geometry>
        <mesh filename="package://jaco_model/meshes/mico_link_finger_2.dae"/>
      </geometry>
      <material name="carbon_fiber">
        <color rgba="0.792156862745098 0.819607843137255 0.933333333333333 1"/>
      </material>
    </visual>
    <collision>
      <geometry>
        <mesh filename="package://jaco_model/meshes/mico_link_finger_2.dae"/>
      </geometry>
    </collision>
  </link>
  <joint name="mico_joint_finger_2" type="revolute">
    <parent link="mico_link_hand"/>
    <child link="mico_link_finger_2"/>
    <axis xyz="0 0 1"/>
    <origin rpy="1.5708 0 0" xyz="-0.030948 0.013746 -0.11107 "/>
    <limit effort="30" lower="0" upper="0.698131700798" velocity="5"/>
  </joint>
  <link name="mico_link_finger_1_distal">
    <visual>
      <geometry>
        <mesh filename="package://jaco_model/meshes/mico_link_finger_1_distal.dae"/>
      </geometry>
      <material name="carbon_fiber">
        <color rgba="0.792156862745098 0.819607843137255 0.933333333333333 1"/>
      </material>
    </visual>
    <collision>
      <geometry>
        <mesh filename="package://jaco_model/meshes/mico_link_finger_1_distal.dae"/>
      </geometry>
    </collision>
  </link>
  <joint name="mico_joint_finger_1_distal" type="revolute">
    <parent link="mico_link_finger_1"/>
    <child link="mico_link_finger_1_distal"/>
    <axis xyz="0 0 1"/>
    <origin rpy="0 0 0" xyz="0.026055 0.035582 0"/>
    <limit effort="30" lower="0" upper="0.698131700798" velocity="5"/>
  </joint>
  <link name="mico_link_finger_2_distal">
    <visual>
      <geometry>
        <mesh filename="package://jaco_model/meshes/mico_link_finger_2_distal.dae"/>
      </geometry>
      <material name="carbon_fiber">
        <color rgba="0.792156862745098 0.819607843137255 0.933333333333333 1"/>
      </material>
    </visual>
    <collision>
      <geometry>
        <mesh filename="package://jaco_model/meshes/mico_link_finger_2_distal.dae"/>
      </geometry>
    </collision>
  </link>
  <joint name="mico_joint_finger_2_distal" type="revolute">
    <parent link="mico_link_finger_2"/>
    <child link="mico_link_finger_2_distal"/>
    <axis xyz="0 0 1"/>
    <origin rpy="0 0 0" xyz="-0.026055 -0.035582 0"/>
    <limit effort="30" lower="0" upper="0.698131700798" velocity="5"/>
  </joint>
</robot>
