
<robot
  name="mico_simplified">

<gazebo>
  <plugin name="gazebo_ros_control" filename="libgazebo_ros_control.so">
    <robotNamespace>/mico_simplified</robotNamespace>
  </plugin>
</gazebo>

<!--
 Trying to get thing to not flail START
  <dynamics damping="0.0" friction="0.0"/>

  <physics type="ode">
  <gravity xyz="0 0 -9.8"/>
  <ode>
    <solver type="quick" dt="0.0001" iters="1000" sor="1.3"/>
    <constraints cfm="0.0" erp="0.1" contact_max_correcting_vel="10.0" contact_surface_layer="0.001"/>
  </ode>
</physics>
-->

<!--Trying to get thing to not flail END -->


  <link name="world"/>
   <joint name="fixed" type="fixed">
    <parent link="world"/>
    <child link="support_box"/>
  </joint>

<!--
  <gazebo>
  <plugin name="gazebo_ros_openni_kinect_controller" filename="libgazebo_ros_openni_kinect.so">
    <baseline>0.2</baseline>
    <alwaysOn>true</alwaysOn>
    <updateRate>1.0</updateRate>
    <cameraName>kinect_ir</cameraName>
    <imageTopicName>/kinect/depth/image_raw</imageTopicName>
    <cameraInfoTopicName>/kinect/depth/camera_info</cameraInfoTopicName>
    <depthImageTopicName>/kinect/depth/image_raw</depthImageTopicName>
    <depthImageInfoTopicName>/kinect/depth/camera_info</depthImageInfoTopicName>
    <pointCloudTopicName>/kinect/depth/points</pointCloudTopicName>
    <frameName>${frame_name}</frameName>
    <pointCloudCutoff>0.5</pointCloudCutoff>
    <distortionK1>0.00000001</distortionK1>
    <distortionK2>0.00000001</distortionK2>
    <distortionK3>0.00000001</distortionK3>
    <distortionT1>0.00000001</distortionT1>
    <distortionT2>0.00000001</distortionT2>
    <CxPrime>0</CxPrime>
    <Cx>0</Cx>
    <Cy>0</Cy>
    <focalLength>0</focalLength>
    <hackBaseline>0</hackBaseline>
  </plugin>
</gazebo>
-->


  <link name="support_box">
    <visual>
      <origin rpy="0 0 0" xyz="0 0 0"/>
      <geometry>
        <box size=".05 .05 .05"/>
        <!--making it slightly bigger in x and z direction-->
      </geometry>
      <material name="Black"/>
    </visual>
    <collision>
      <origin rpy="0 0 0" xyz="0 0 0"/>
      <geometry>
        <box size=".05 .05 .05"/>
        <!--making it slightly bigger in x and z direction-->
      </geometry>
    </collision>
  </link>

   <joint name="jaco_joint_base" type="fixed">
    <parent link="support_box"/>
    <child link="base_link"/>
    <axis xyz="0 0 0"/>
    <origin rpy="0 0 0" xyz="0 0 0"/>
  </joint>

  <link
    name="base_link">
    <inertial>
      <origin
        xyz="0.0018698 4.3975E-06 0.00076788"
        rpy="0 0 0" />
      <mass
        value="1.4" />
      <inertia
        ixx="0.00058911"
        ixy="-1.7836E-08"
        ixz="-8.7807E-06"
        iyy="0.00059853"
        iyz="4.7608E-08"
        izz="0.00031086" />
    </inertial>
    <visual>
      <origin
        xyz="0 0 0"
        rpy="0 0 0" />
      <geometry>
        <mesh
          filename="package://mico_simplified/meshes/base_link.STL" />
      </geometry>
      <material
        name="">
        <color
          rgba="0.79216 0.81961 0.93333 1" />
      </material>
    </visual>
    <collision>
      <origin
        xyz="0 0 0"
        rpy="0 0 0" />
      <geometry>
        <mesh
          filename="package://mico_simplified/meshes/base_link.STL" />
      </geometry>
    </collision>
  </link>
  <link
    name="Shoulder_Link">
    <inertial>
      <origin
        xyz="9.8364E-07 0.014125 -0.070452"
        rpy="0 0 0" />
      <mass
        value="0.76" />
      <inertia
        ixx="0.00044618"
        ixy="-2.0592E-08"
        ixz="-9.2286E-09"
        iyy="0.00047056"
        iyz="-7.4063E-05"
        izz="0.00019269" />
    </inertial>
    <visual>
      <origin
        xyz="0 0 0"
        rpy="0 0 0" />
      <geometry>
        <mesh
          filename="package://mico_simplified/meshes/Shoulder_Link.STL" />
      </geometry>
      <material
        name="">
        <color
          rgba="0.79216 0.81961 0.93333 1" />
      </material>
    </visual>
    <collision>
      <origin
        xyz="0 0 0"
        rpy="0 0 0" />
      <geometry>
        <mesh
          filename="package://mico_simplified/meshes/Shoulder_Link.STL" />
      </geometry>
    </collision>
  </link>
  <joint
    name="Shoulder_Joint"
    type="revolute">
    <origin
      xyz="0 0 0.09425"
      rpy="-3.1416 4.3794E-14 1.8406E-28" />
    <parent
      link="base_link" />
    <child
      link="Shoulder_Link" />
    <axis
      xyz="0 0 1" />
    <limit
      lower="-3.14"
      upper="3.14"
      effort="1000"
      velocity="1" />
       <dynamics damping="1"/>
        <safety_controller k_position="100" k_velocity="10"
                         soft_lower_limit="-3.14" soft_upper_limit="3.14" />
  </joint>
  <link
    name="Arm_Link">
    <inertial>
      <origin
        xyz="-1.5264E-05 0.13777 -0.021034"
        rpy="0 0 0" />
      <mass
        value="0.76" />
      <inertia
        ixx="0.0036974"
        ixy="-7.8568E-08"
        ixz="4.7633E-08"
        iyy="0.00022818"
        iyz="-5.7314E-05"
        izz="0.0038268" />
    </inertial>
    <visual>
      <origin
        xyz="0 0 0"
        rpy="0 0 0" />
      <geometry>
        <mesh
          filename="package://mico_simplified/meshes/Arm_Link.STL" />
      </geometry>
      <material
        name="">
        <color
          rgba="0.79216 0.81961 0.93333 1" />
      </material>
    </visual>
    <collision>
      <origin
        xyz="0 0 0"
        rpy="0 0 0" />
      <geometry>
        <mesh
          filename="package://mico_simplified/meshes/Arm_Link.STL" />
      </geometry>
    </collision>
  </link>
  <joint
    name="Arm_Joint"
    type="revolute">
    <origin
      xyz="0 -0.00625 -0.12325"
      rpy="-1.5708 4.3794E-14 0" />
    <parent
      link="Shoulder_Link" />
    <child
      link="Arm_Link" />
    <axis
      xyz="0 0 1" />
    <limit
      lower="-2.26"
      upper="2.26"
      effort="1000"
      velocity="1" />    
       <dynamics damping="1"/>
      <safety_controller k_position="100" k_velocity="10"
                         soft_lower_limit="-2.26" soft_upper_limit="2.26" />
  </joint>
  <link
    name="Forearm_Link">
    <inertial>
      <origin
        xyz="3.3265E-06 0.035568 -0.023918"
        rpy="0 0 0" />
      <mass
        value="0.4" />
      <inertia
        ixx="0.00029276"
        ixy="2.9256E-08"
        ixz="4.5147E-08"
        iyy="0.00011211"
        iyz="1.2704E-05"
        izz="0.00033531" />
    </inertial>
    <visual>
      <origin
        xyz="0 0 0"
        rpy="0 0 0" />
      <geometry>
        <mesh
          filename="package://mico_simplified/meshes/Forearm_Link.STL" />
      </geometry>
      <material
        name="">
        <color
          rgba="0.79216 0.81961 0.93333 1" />
      </material>
    </visual>
    <collision>
      <origin
        xyz="0 0 0"
        rpy="0 0 0" />
      <geometry>
        <mesh
          filename="package://mico_simplified/meshes/Forearm_Link.STL" />
      </geometry>
    </collision>
  </link>
  <joint
    name="Forearm_Joint"
    type="revolute">
    <origin
      xyz="0 0.29 0"
      rpy="3.1416 0 3.1416" />
    <parent
      link="Arm_Link" />
    <child
      link="Forearm_Link" />
    <axis
      xyz="0 0 -1" />
    <limit
      lower="-2.44"
      upper="2.44"
      effort="1000"
      velocity="1" />
       <dynamics damping="1"/>
        <safety_controller k_position="100" k_velocity="10"
                        soft_lower_limit="-2.44" soft_upper_limit="2.44" />
  </joint>
  <link
    name="Wrist_1_Link">
    <inertial>
      <origin
        xyz="-3.8615E-05 0.0067766 -0.027417"
        rpy="0 0 0" />
      <mass
        value="0.4" />
      <inertia
        ixx="4.9442E-05"
        ixy="-2.5359E-08"
        ixz="2.3947E-08"
        iyy="4.949E-05"
        iyz="-5.6364E-06"
        izz="4.0284E-05" />
    </inertial>
    <visual>
      <origin
        xyz="0 0 0"
        rpy="0 0 0" />
      <geometry>
        <mesh
          filename="package://mico_simplified/meshes/Wrist_1_Link.STL" />
      </geometry>
      <material
        name="">
        <color
          rgba="0.79216 0.81961 0.93333 1" />
      </material>
    </visual>
    <collision>
      <origin
        xyz="0 0 0"
        rpy="0 0 0" />
      <geometry>
        <mesh
          filename="package://mico_simplified/meshes/Wrist_1_Link.STL" />
      </geometry>
    </collision>
  </link>
  <joint
    name="Wrist_1_Joint"
    type="revolute">
    <origin
      xyz="0 0.127 -0.01325"
      rpy="1.5708 -2.3904E-31 6.8996E-15" />
    <parent
      link="Forearm_Link" />
    <child
      link="Wrist_1_Link" />
    <axis
      xyz="0 0 -1" />
    <limit
      lower="-3.14"
      upper="3.14"
      effort="1000"
      velocity="10" />
       <dynamics damping="1"/>
  </joint>
  <link
    name="Wrist_2_Link">
    <inertial>
      <origin
        xyz="3.8855E-05 -0.006776 -0.027417"
        rpy="0 0 0" />
      <mass
        value="0.4" />
      <inertia
        ixx="4.9444E-05"
        ixy="-2.4795E-08"
        ixz="-2.4072E-08"
        iyy="4.949E-05"
        iyz="5.635E-06"
        izz="4.0281E-05" />
    </inertial>
    <visual>
      <origin
        xyz="0 0 0"
        rpy="0 0 0" />
      <geometry>
        <mesh
          filename="package://mico_simplified/meshes/Wrist_2_Link.STL" />
      </geometry>
      <material
        name="">
        <color
          rgba="0.79216 0.81961 0.93333 1" />
      </material>
    </visual>
    <collision>
      <origin
        xyz="0 0 0"
        rpy="0 0 0" />
      <geometry>
        <mesh
          filename="package://mico_simplified/meshes/Wrist_2_Link.STL" />
      </geometry>
    </collision>
  </link>
  <joint
    name="Wrist_2_Joint"
    type="revolute">
    <origin
      xyz="0 0.040276 -0.062261"
      rpy="1.0472 -1.1202E-14 -7.4515E-15" />
    <parent
      link="Wrist_1_Link" />
    <child
      link="Wrist_2_Link" />
    <axis
      xyz="0 0 -1" />
    <limit
      lower="-3.14"
      upper="3.14"
      effort="1000"
      velocity="10" />
       <dynamics damping="1"/>
       <safety_controller k_position="100" k_velocity="10"
         soft_lower_limit="-3.1" soft_upper_limit="3.1" />
  </joint>
  <link
    name="Hand_Link">
    <inertial>
      <origin
        xyz="-0.0014195 7.8354E-06 -0.066076"
        rpy="0 0 0" />
      <mass
        value="0.4" />
      <inertia
        ixx="0.00025595"
        ixy="-1.199E-08"
        ixz="4.5804E-06"
        iyy="0.00020193"
        iyz="5.0676E-08"
        izz="0.00013393" />
    </inertial>
    <visual>
      <origin
        xyz="0 0 0"
        rpy="0 0 0" />
      <geometry>
        <mesh
          filename="package://mico_simplified/meshes/Hand_Link.STL" />
      </geometry>
      <material
        name="">
        <color
          rgba="0.79216 0.81961 0.93333 1" />
      </material>
    </visual>
    <collision>
      <origin
        xyz="0 0 0"
        rpy="0 0 0" />
      <geometry>
        <mesh
          filename="package://mico_simplified/meshes/Hand_Link.STL" />
      </geometry>
    </collision>
  </link>
  <joint
    name="Hand_Joint"
    type="revolute">
    <origin
      xyz="0 -0.040276 -0.062261"
      rpy="-1.0472 4.7648E-15 6.6501E-15" />
    <parent
      link="Wrist_2_Link" />
    <child
      link="Hand_Link" />
    <axis
      xyz="0 0 1" />
    <limit
      lower="-3.14"
      upper="3.14"
      effort="1000"
      velocity="1" />
    <dynamics damping="0.01" />
          <safety_controller k_position="100" k_velocity="10"
                         soft_lower_limit="-3.1" soft_upper_limit="3.1" />
  </joint>
  <link
    name="Finger_1_Proximal_Link">
    
    <inertial>
      <origin
        xyz="0.0172616572113394 0.0105538611465319 -0.0112506191776746"
        rpy="0 0 0" />
          <mass
        value="0.4" />
      <inertia
        ixx="0.00025595"
        ixy="-1.199E-08"
        ixz="4.5804E-06"
        iyy="0.00020193"
        iyz="5.0676E-08"
        izz="0.00013393" />
  </inertial>
    <visual>
      <origin
        xyz="0 0 0"
        rpy="0 0 0" />
      <geometry>
        <mesh
          filename="package://mico_simplified/meshes/Finger_1_Proximal_Link.STL" />
      </geometry>
      <material
        name="">
        <color
          rgba="0.792156862745098 0.819607843137255 0.933333333333333 1" />
      </material>
    </visual>
    <collision>
      <origin
        xyz="0 0 0"
        rpy="0 0 0" />
      <geometry>
        <mesh
          filename="package://mico_simplified/meshes/Finger_1_Proximal_Link.STL" />
      </geometry>
    </collision>
  </link>
  <joint
    name="Finger_1_Proximal_Joint"
    type="revolute">
    <origin
      xyz="-0.013746 0.030948 -0.11107"
      rpy="-1.5708 3.3457E-16 1.5708" />
    <parent
      link="Hand_Link" />
    <child
      link="Finger_1_Proximal_Link" />
    <axis
      xyz="0 0 1" />
    <limit
      lower="-0.001"
      upper="0.78"
      effort="100"
      velocity="1" />
    <dynamics damping="0.01" />
          <safety_controller k_position="100" k_velocity="10"
                         soft_lower_limit="-0.1" soft_upper_limit=".75" />
  </joint>
  <link
    name="Finger_1_Distal_Link">
    <inertial>
      <origin
        xyz="0.0126210373400246 0.00643480436760779 -0.0112500681940836"
        rpy="0 0 0" />
          <mass
        value="0.4" />
      <inertia
        ixx="0.00025595"
        ixy="-1.199E-08"
        ixz="4.5804E-06"
        iyy="0.00020193"
        iyz="5.0676E-08"
        izz="0.00013393" />      
    </inertial>
    <visual>
      <origin
        xyz="0 0 0"
        rpy="0 0 0" />
      <geometry>
        <mesh
          filename="package://mico_simplified/meshes/Finger_1_Distal_Link.STL" />
      </geometry>
      <material
        name="">
        <color
          rgba="0.792156862745098 0.819607843137255 0.933333333333333 1" />
      </material>
    </visual>
    <collision>
      <origin
        xyz="0 0 0"
        rpy="0 0 0" />
      <geometry>
        <mesh
          filename="package://mico_simplified/meshes/Finger_1_Distal_Link.STL" />
      </geometry>
    </collision>
  </link>
  <joint
    name="Finger_1_Distal_Joint"
    type="revolute">
    <origin
      xyz="0.026055 0.035582 0"
      rpy="-4.0279E-17 6.1154E-17 -4.7179E-31" />
    <parent
      link="Finger_1_Proximal_Link" />
    <child
      link="Finger_1_Distal_Link" />
    <axis
      xyz="0 0 -1" />
    <limit
      lower="-0.001"
      upper="0.78"
      effort="100"
      velocity="1" />
    <dynamics damping="0.01" />
      <safety_controller k_position="100" k_velocity="10"
                         soft_lower_limit="-0.1" soft_upper_limit=".75" />
  </joint>
  <link
    name="Finger_2_Proximal_Link">
    <inertial>
      <origin
        xyz="-0.0172616584345737 -0.0105538552511416 0.0112493808527515"
        rpy="0 0 0" />
          <mass
        value="0.4" />
      <inertia
        ixx="0.00025595"
        ixy="-1.199E-08"
        ixz="4.5804E-06"
        iyy="0.00020193"
        iyz="5.0676E-08"
        izz="0.00013393" />   
    </inertial>
    <visual>
      <origin
        xyz="0 0 0"
        rpy="0 0 0" />
      <geometry>
        <mesh
          filename="package://mico_simplified/meshes/Finger_2_Proximal_Link.STL" />
      </geometry>
      <material
        name="">
        <color
          rgba="0.792156862745098 0.819607843137255 0.933333333333333 1" />
      </material>
    </visual>
    <collision>
      <origin
        xyz="0 0 0"
        rpy="0 0 0" />
      <geometry>
        <mesh
          filename="package://mico_simplified/meshes/Finger_2_Proximal_Link.STL" />
      </geometry>
    </collision>
  </link>
  <joint
    name="Finger_2_Proximal_Joint"
    type="revolute">
    <origin
      xyz="-0.013746 -0.030948 -0.11107"
      rpy="1.5708 3.3457E-16 1.5708" />
    <parent
      link="Hand_Link" />
    <child
      link="Finger_2_Proximal_Link" />
    <axis
      xyz="0 0 1" />
    <limit
      lower="-0.001"
      upper="0.78"
      effort="100"
      velocity="1" />
    <dynamics damping="0.01" />
      <safety_controller k_position="5000" k_velocity="20"
                         soft_lower_limit="-0.1" soft_upper_limit=".75" />
  </joint>
  <link
    name="Finger_2_Distal_Link">
    <inertial>
      <origin
        xyz="-0.0126210373425155 -0.00643480437565225 0.0112499318045061"
        rpy="0 0 0" />
          <mass
        value="0.4" />
      <inertia
        ixx="0.00025595"
        ixy="-1.199E-08"
        ixz="4.5804E-06"
        iyy="0.00020193"
        iyz="5.0676E-08"
        izz="0.00013393" />
    </inertial>
    <visual>
      <origin
        xyz="0 0 0"
        rpy="0 0 0" />
      <geometry>
        <mesh
          filename="package://mico_simplified/meshes/Finger_2_Distal_Link.STL" />
      </geometry>
      <material
        name="">
        <color
          rgba="0.792156862745098 0.819607843137255 0.933333333333333 1" />
      </material>
    </visual>
    <collision>
      <origin
        xyz="0 0 0"
        rpy="0 0 0" />
      <geometry>
        <mesh
          filename="package://mico_simplified/meshes/Finger_2_Distal_Link.STL" />
      </geometry>
    </collision>
  </link>
  <joint
    name="Finger_2_Distal_Joint"
    type="revolute">
    <origin
      xyz="-0.026055 -0.035582 0"
      rpy="4.8081E-17 -4.6577E-17 -5.6023E-31" />
    <parent
      link="Finger_2_Proximal_Link" />
    <child
      link="Finger_2_Distal_Link" />
    <axis
      xyz="0 0 -1" />
    <limit
      lower="-0.01"
      upper="0.78"
      effort="100"
      velocity=".2" />
    <dynamics damping="0.001" />
      <safety_controller k_position="5000" k_velocity="20"
                         soft_lower_limit="-0.1" soft_upper_limit=".75" />
  </joint>

  <transmission name="tran1">
    <type>transmission_interface/SimpleTransmission</type>
    <joint name="Finger_1_Distal_Joint"/>
    <actuator name="motor1">
      <hardwareInterface>EffortJointInterface</hardwareInterface>
      <mechanicalReduction>1</mechanicalReduction>
    </actuator>
  </transmission>

  <transmission name="tran2">
    <type>transmission_interface/SimpleTransmission</type>
    <joint name="Finger_2_Distal_Joint"/>
    <actuator name="motor2">
      <hardwareInterface>EffortJointInterface</hardwareInterface>
      <mechanicalReduction>1</mechanicalReduction>
    </actuator>
  </transmission>

    <transmission name="tran3">
    <type>transmission_interface/SimpleTransmission</type>
    <joint name="Finger_1_Proximal_Joint"/>
    <actuator name="motor3">
      <hardwareInterface>EffortJointInterface</hardwareInterface>
      <mechanicalReduction>1</mechanicalReduction>
    </actuator>
  </transmission>
  <transmission name="tran4">
    <type>transmission_interface/SimpleTransmission</type>
    <joint name="Finger_2_Proximal_Joint"/>
    <actuator name="motor4">
      <hardwareInterface>EffortJointInterface</hardwareInterface>
      <mechanicalReduction>1</mechanicalReduction>
    </actuator>
  </transmission>

    <transmission name="tran5">
    <type>transmission_interface/SimpleTransmission</type>
    <joint name="Hand_Joint"/>
    <actuator name="motor5">
      <hardwareInterface>EffortJointInterface</hardwareInterface>
      <mechanicalReduction>1</mechanicalReduction>
    </actuator>
  </transmission>

   <transmission name="tran10">
    <type>transmission_interface/SimpleTransmission</type>
    <joint name="Forearm_Joint"/>
    <actuator name="motor10">
      <hardwareInterface>EffortJointInterface</hardwareInterface>
      <mechanicalReduction>1</mechanicalReduction>
    </actuator>
  </transmission>

  <transmission name="tran6">
    <type>transmission_interface/SimpleTransmission</type>
    <joint name="Wrist_1_Joint"/>
    <actuator name="motor6">
      <hardwareInterface>EffortJointInterface</hardwareInterface>
      <mechanicalReduction>1</mechanicalReduction>
    </actuator>
  </transmission>

    <transmission name="tran7">
    <type>transmission_interface/SimpleTransmission</type>
    <joint name="Wrist_2_Joint"/>
    <actuator name="motor7">
      <hardwareInterface>EffortJointInterface</hardwareInterface>
      <mechanicalReduction>1</mechanicalReduction>
    </actuator>
  </transmission>

  <transmission name="tran8">
    <type>transmission_interface/SimpleTransmission</type>
    <joint name="Arm_Joint"/>
    <actuator name="motor8">
      <hardwareInterface>EffortJointInterface</hardwareInterface>
      <mechanicalReduction>1</mechanicalReduction>
    </actuator>
  </transmission>

    <transmission name="tran9">
    <type>transmission_interface/SimpleTransmission</type>
    <joint name="Shoulder_Joint"/>
    <actuator name="motor9">
      <hardwareInterface>EffortJointInterface</hardwareInterface>
      <mechanicalReduction>1</mechanicalReduction>
    </actuator>
  </transmission>

</robot>